Workbook

Sheet README — How to Use
A1: RAG SCREENING SHEET WORKBOOK | ESADE MSc Finance | Sustainable Finance | May 2026 Academic Prototype — Not Investment Advice — Not a Regulated ESG Product
A2: NINE-STEP WORKFLOW
A3: Step 1 | B3: Paste company identifiers | C3: Universe Tracker sheet → paste Company Name, Ticker, ISIN, Country, BICS Sector. One row per company. Row ID is calculated automatically.
A4: Step 2 | B4: Assign review priority | C4: Universe Tracker → Review Priority column. Deep Review = 10–12 companies for full Claude Project extraction. Light Screen = remaining 38–40.
A5: Step 3 | B5: Collect source documents | C5: For each Deep Review company: sustainability report PDF, annual report (if ESG-relevant), TCFD report, assurance statement. Log all in Source Register sheet.
A6: Step 4 | B6: Run RAG extraction in Claude Project | C6: Create one Claude Project per Deep Review company. Upload PDFs. Paste system prompt from 8-Test Greenwashing sheet. Run extraction. Save JSON output.
A7: Step 5 | B7: Paste outputs into RAG Screening Sheet | C7: Copy extracted evidence into relevant columns. Mark each cell with its source document and page reference. Use evidence confidence dropdowns.
A8: Step 6 | B8: Verify source evidence manually | C8: Verify ≥30% of all extractions against source PDF. 100% verification for any Watchlist or Exclusion flag. Record in Verification Log sheet.
A9: Step 7 | B9: Review scores and flags | C9: Check auto-calculated columns (G12–G15, G21, G22, H10–H12, I6, I7). Review any triggered flags. Note: C19, D12, E13, F11 require manual formula implementation — see Scoring Logic sheet.
A10: Step 8 | B10: Assign final RAG verdict | C10: Review I7 auto-verdict. Override in I8 if human judgement requires it. Document rationale in I10. Never leave I10 blank for Watchlist or Exclusion verdicts.
A11: Step 9 | B11: Handoff | C11: Pipeline Operator → JSON schema from JSON Output Schema sheet. ESG Specialist → indicator columns + Verification Log. Captain → Watchlist & Exclusion Summary sheet.
A13: COLOUR CODING
A14: Green fill | B14: Strong evidence / PASS | C14: Apply manually to cells with strong supporting evidence
A15: Amber fill | B15: Partial evidence / PARTIAL / see note | C15: Used automatically for C19/D12/E13/F11 placeholder cells (requires formula implementation)
A16: Red fill | B16: Failed test / hard exclusion trigger | C16: Apply manually to cells triggering hard exclusion
A17: Grey fill | B17: MISSING — evidence not found | C17: Apply manually when evidence is absent
A18: Yellow fill | B18: Unverified — human check required | C18: Apply when verification is pending
A20: IMPORTANT CONSTRAINTS
A21: Missing ≠ Good | B21: Absence of evidence is a risk signal, not positive evidence | C21: A company that does not disclose a metric receives no positive score for it
A22: Disclosure ≠ Performance | B22: Disclosing Scope 3 data ≠ performing well on Scope 3 | C22: Only the actual figures determine the climate score
A23: Eligibility ≠ Alignment | B23: EU Taxonomy eligible revenue ≠ aligned revenue | C23: Do not use eligibility to meet the ≥50% alignment mandate target
A24: Score ≠ Truth | B24: This model produces signals, not verdicts | C24: Human review required at all Watchlist and Exclusion decisions
A25: AI flags. Humans decide. Everything is logged. | B25: Core operating principle of this workbook | C25: All verdicts are subject to Captain and ESG Specialist confirmation
A27: SHEET DIRECTORY
A28: Sheet | B28: Purpose | C28: Owned By
A29: RAG Screening Sheet | B29: Main working sheet — one row per company, all groups A–I | C29: RAG Operator
A30: Universe Tracker | B30: 50-company master list with review priority and status | C30: RAG Operator / Data Engineer
A31: Watchlist & Exclusion Summary | B31: Decision-ready flags for Captain and ESG Specialist | C31: RAG Operator
A32: 8-Test Greenwashing | B32: Test definitions, pass/fail criteria, Claude Project system prompt | C32: RAG Operator
A33: Scoring Logic | B33: All formulas, weights, override rules, scoring point tables | C33: RAG Operator
A34: Biodiversity Framework | B34: ENCORE / WWF / Aqueduct / TNFD methodology reference | C34: RAG Operator
A35: Verification Log | B35: Manual verification records — 30% sample minimum | C35: RAG Operator
A36: Source Register | B36: All documents reviewed with URL and citation format | C36: RAG Operator
A37: Factor Definitions | B37: Academic rationale for every screening dimension | C37: RAG Operator
A38: Data Dictionary | B38: Glossary of all terms and abbreviations | C38: RAG Operator
A39: JSON Output Schema | B39: JSON structure for Pipeline Operator handoff | C39: RAG Operator / Pipeline Operator
A40: Disclaimer & Limitations | B40: Anti-overclaiming language — extract for Section 11 | C40: RAG Operator

Sheet RAG Screening Sheet
A1: RAG SCREENING SHEET | ESADE Sustainable Finance | Academic Prototype — Not Investment Advice | v1.0
A2: A — COMPANY IDENTIFIERS | K2: B — DOCUMENT COVERAGE | Z2: C — CLIMATE CLAIM CREDIBILITY | AT2: D — ESG SAFEGUARDS | BG2: E — BIODIVERSITY / NATURE-RISK | BU2: F — EU REGULATION / TAXONOMY | CG2: G — CONTROVERSY & GREENWASHING (8-TEST) | DC2: H — EVIDENCE QUALITY & VERIFICATION | DO2: I — FINAL RAG OUTPUT | EB2: J — SUMMARY TAB
A3: A | B3: A | C3: A | D3: A | E3: A | F3: A | G3: A | H3: A | I3: A | J3: A | K3: B | L3: B | M3: B | N3: B | O3: B | P3: B | Q3: B | R3: B | S3: B | T3: B | U3: B | V3: B | W3: B | X3: B | Y3: B | Z3: C | AA3: C | AB3: C | AC3: C | AD3: C | AE3: C | AF3: C | AG3: C | AH3: C | AI3: C | AJ3: C | AK3: C | AL3: C | AM3: C | AN3: C | AO3: C | AP3: C | AQ3: C | AR3: C | AS3: C | AT3: D | AU3: D | AV3: D | AW3: D | AX3: D | AY3: D | AZ3: D | BA3: D | BB3: D | BC3: D | BD3: D | BE3: D | BF3: D | BG3: E | BH3: E | BI3: E | BJ3: E | BK3: E | BL3: E | BM3: E | BN3: E | BO3: E | BP3: E | BQ3: E | BR3: E | BS3: E | BT3: E | BU3: F | BV3: F | BW3: F | BX3: F | BY3: F | BZ3: F | CA3: F | CB3: F | CC3: F | CD3: F | CE3: F | CF3: F | CG3: G | CH3: G | CI3: G | CJ3: G | CK3: G | CL3: G | CM3: G | CN3: G | CO3: G | CP3: G | CQ3: G | CR3: G | CS3: G | CT3: G | CU3: G | CV3: G | CW3: G | CX3: G | CY3: G | CZ3: G | DA3: G | DB3: G | DC3: H | DD3: H | DE3: H | DF3: H | DG3: H | DH3: H | DI3: H | DJ3: H | DK3: H | DL3: H | DM3: H | DN3: H | DO3: I | DP3: I | DQ3: I | DR3: I | DS3: I | DT3: I | DU3: I | DV3: I | DW3: I | DX3: I | DY3: I | DZ3: I | EA3: I | EB3: J | EC3: J | ED3: J | EE3: J | EF3: J
A4: 1 | B4: =A4+1 | C4: =B4+1 | D4: =C4+1 | E4: =D4+1 | F4: =E4+1 | G4: =F4+1 | H4: =G4+1 | I4: =H4+1 | ... EF4: =EE4+1
A5: =CONCATENATE(A3,A4) | B5: =CONCATENATE(B3,B4) | C5: =CONCATENATE(C3,C4) | D5: =CONCATENATE(D3,D4) | E5: =CONCATENATE(E3,E4) | F5: =CONCATENATE(F3,F4) | G5: =CONCATENATE(G3,G4) | H5: =CONCATENATE(H3,H4) | ... EF5: =CONCATENATE(EF3,EF4)
A6: Company Name | B6: Ticker | C6: ISIN | D6: Country (Incorporation) | E6: Country (Domicile) | F6: BICS Sector | G6: BICS Industry | H6: Universe Status | I6: Review Priority | J6: Row ID [auto] | K6: Annual Report Available? | L6: Sustainability Report Available? | M6: TCFD Report Available? | N6: CSRD / ESRS Disclosure? | O6: SBTi Database Checked? | P6: TPI Checked? | Q6: CA100+ Checked? | R6: ENCORE Checked? | S6: WWF BRF Checked? | T6: WRI Aqueduct Checked? | U6: Controversy Search Done? | V6: # Sources Reviewed | W6: Most Recent Report Year | X6: Data Vintage Note | Y6: Doc Coverage Flag [auto] | Z6: Net-Zero Target Claimed? | AA6: Net-Zero Target Year | AB6: Interim Target Stated? | AC6: Interim Target Year | AD6: Interim Target % Reduction | AE6: Interim Target Baseline Year | AF6: Scope 1+2 Coverage | AG6: Scope 3 Disclosed? | AH6: Scope 3 Categories Count (of 15) | AI6: Scope 3 Included in Target? | AJ6: SBTi Status | AK6: SBTi Approval Year | AL6: Transition Plan Disclosed? | AM6: Capex Alignment Evidence? | AN6: Capex Alignment Quote | AO6: Capex % Sustainable | AP6: Climate Governance Evidence | AQ6: Lobbying Consistency | AR6: Climate Credibility Score [auto] | AS6: Climate Red Flag | AT6: HR Policy Status | AU6: HR Policy Page Ref | AV6: UNGC Signatory? | AW6: UNGC Violation Evidence | AX6: OECD MNE Compliance | AY6: Supply Chain DD Evidence | AZ6: Labour / H&S Controversy | BA6: Board Sustainability Oversight | BB6: ESG-Linked Exec Pay | BC6: ESG Data Assurance | BD6: Assurance Provider | BE6: Safeguards Score [auto] | BF6: Safeguards Red Flag | BG6: Biodiversity Policy | BH6: Nature Dependency (ENCORE) | BI6: Nature Impact (ENCORE) | BJ6: Water Risk (WRI Aqueduct) | BK6: Land Use Exposure | BL6: Pollution / Waste Exposure | BM6: Biodiversity-Sensitive Sites | BN6: PAI 7 Relevance | BO6: PAI 7 % Revenue | BP6: Sector Nature Risk Class | BQ6: Mitigation Hierarchy Evidence | BR6: TNFD Alignment | BS6: Biodiversity Score [auto] | BT6: Nature-Risk Red Flag | BU6: Taxonomy Eligibility Source | BV6: Taxonomy Eligible Revenue % | BW6: Taxonomy Aligned Revenue % | BX6: Taxonomy Aligned Capex % | BY6: Alignment Company-Stated? | BZ6: DNSH Evidence | CA6: Minimum Safeguards Evidence | CB6: PAI Indicators Reported (of 18) | CC6: CSRD / ESRS Disclosure Quality | CD6: SFDR Fund Classification (self) | CE6: EU Reg Evidence Score [auto] | CF6: EU Reg Red Flag | CG6: Main Claim Tested | CH6: Claim Source Document | CI6: Claim Page / Section Ref | CJ6: 8-Test 1: Specificity | CK6: 8-Test 2: Metric | CL6: 8-Test 3: Baseline | CM6: 8-Test 4: Target | CN6: 8-Test 5: Time Horizon | CO6: 8-Test 6: Scope | CP6: 8-Test 7: Verification | CQ6: 8-Test 8: Consistency | CR6: # Tests FAILED [auto] | CS6: # Tests PARTIAL [auto] | CT6: # Tests MISSING [auto] | CU6: Greenwashing Risk Score [auto] | CV6: Worst Dimension | CW6: Controversy Severity | CX6: Controversy Description | CY6: Controversy Source | CZ6: Controversy Date | DA6: Watchlist Trigger [auto] | DB6: Exclusion Trigger [auto] | DC6: Key Evidence Quote | DD6: Key Evidence Source Doc | DE6: Key Evidence Page Ref | DF6: Evidence Confidence (1–5) | DG6: AI Extraction Confidence (1–5) | DH6: Verification Status | DI6: Verified By | DJ6: Verification Date | DK6: Verification Notes | DL6: Low-Confidence Flag [auto] | DM6: Human Review Required [auto] | DN6: Evidence Quality Score [auto] | DO6: Climate Verdict | DP6: Biodiversity Verdict | DQ6: Safeguards Verdict | DR6: Greenwashing Verdict | DS6: EU Reg Verdict | DT6: Overall RAG Score [auto] | DU6: Final RAG Verdict [auto] | DV6: Human Override | DW6: Recommended Action | DX6: Verdict Rationale | DY6: Open Questions | DZ6: Handoff Owner | EA6: Handoff Status | EB6: Missing Source Flag | EC6: Missing Page Reference Flag | ED6: Verified Evidence Count | EE6: Verification Completion Percentage | EF6: Companies Ready for Handoff
A7: Next PLC | B7: NXG | C7: =IF(ISBLANK('Universe Tracker'!D3),"",'Universe Tracker'!D3) | F7: =IF(ISBLANK('Universe Tracker'!F3),"",'Universe Tracker'!F3) | G7: =IF(ISBLANK('Universe Tracker'!G3),"",'Universe Tracker'!G3) | J7: =IF(ISBLANK(B7),"",B7&"_"&C7) | Y7: =IF(AND(V7>=2,K7="Yes",L7="Yes"),"Sufficient",IF(AND(V7>=1,OR(K7="Yes",L7="Yes")),"Thin","Insufficient")) | AR7: {=MIN(100, MAX(0, IFERROR(_xlfn.XLOOKUP(AJ7,'Lookup Tables'!$A$2:$A$7,'Lookup Tables'!$B$2:$B$7,0),0) + IF(Z7="Yes", IF(IFERROR(_xlfn.XLOOKUP(AJ7,'Lookup Tables'!$A$2:$A$7,'Lookup Tables'!$B$2:$B$7,0),0)<20, 5, 0), 0) + _xlfn.IFS(AB7="Yes", IF(ISNUMBER(AC7)*AND(AC7<=2030),15,10), AB7="Long-term Only", 5, AB7="No", 0, TRUE, 0) + _xlfn.IFS(AF7="Full",10, AF7="Partial",5, AF7="Scope 2 Only",3, TRUE,0) + _xlfn.IFS(AG7="Yes", IF(ISNUMBER(AH7)*AND(AH7>=5),10,6), AG7="Partial",4, TRUE,0) + _xlfn.IFS(AI7="Yes",5, AI7="Partial (material categories only)",3, TRUE,0) + _xlfn.IFS(AL7="Yes — Detailed",10, AL7="Yes — High Level",5, TRUE,0) + _xlfn.IFS(AM7="Yes — Quantified",15, AM7="Yes — Directional Only",7, TRUE,0) + _xlfn.IFS(AP7="Formal",5, AP7="Referenced",2, TRUE,0) + _xlfn.IFS(AQ7="No Issues Found",5, AQ7="Concern Identified",-5, AQ7="Severe Contradiction",-15, TRUE,0) + _xlfn.IFS(BC7="Reasonable Assurance",5, BC7="Limited Assurance",3, TRUE,0) - IF(AND(Z7="Yes", AI7="No"), 10, 0) - IF(AND(Z7="Yes", AM7="No"), 10, 0) ))} | BE7: {=MIN(100, MAX(0, IFERROR(_xlfn.XLOOKUP(AT7,'Lookup Tables'!$D$2:$D$6,'Lookup Tables'!$E$2:$E$6,0),0) + IFERROR(_xlfn.XLOOKUP(AV7,'Lookup Tables'!$G$2:$G$5,'Lookup Tables'!$H$2:$H$5,0),0) + IFERROR(_xlfn.XLOOKUP(AW7,'Lookup Tables'!$J$2:$J$5,'Lookup Tables'!$K$2:$K$5,0),0) + _xlfn.IFS(AX7="No Issues",10, AX7="Complaint Filed",3, AX7="Confirmed Breach",-15, TRUE,0) + IFERROR(_xlfn.XLOOKUP(AY7,'Lookup Tables'!$M$2:$M$6,'Lookup Tables'!$N$2:$N$6,0),0) + IFERROR(_xlfn.XLOOKUP(AZ7,'Lookup Tables'!$P$2:$P$6,'Lookup Tables'!$Q$2:$Q$6,0),0) + _xlfn.IFS(BA7="Formal Board Committee",5, BA7="Board Oversight Mentioned",2, TRUE,0) + _xlfn.IFS(BB7="Yes — Quantified Targets",5, BB7="Yes — Discretionary Only",2, TRUE,0) + _xlfn.IFS(BC7="Reasonable Assurance",5, BC7="Limited Assurance",3, BC7="Management Review Only",1, TRUE,0) ))} | BS7: {=MIN(100, MAX(0, IFERROR(_xlfn.XLOOKUP(BG7,'Lookup Tables'!$A$11:$A$16,'Lookup Tables'!$B$11:$B$16,0),0) + IFERROR(_xlfn.XLOOKUP(BR7,'Lookup Tables'!$M$11:$M$14,'Lookup Tables'!$N$11:$N$14,0),0) + IFERROR(_xlfn.XLOOKUP(BQ7,'Lookup Tables'!$J$11:$J$15,'Lookup Tables'!$K$11:$K$15,0),0) + IFERROR(_xlfn.XLOOKUP(BH7,'Lookup Tables'!$D$11:$D$15,'Lookup Tables'!$E$11:$E$15,0),0) + IFERROR(_xlfn.XLOOKUP(BJ7,'Lookup Tables'!$G$11:$G$16,'Lookup Tables'!$H$11:$H$16,0),0) + IFERROR(_xlfn.XLOOKUP(BN7,'Lookup Tables'!$P$11:$P$15,'Lookup Tables'!$Q$11:$Q$15,0),0) + _xlfn.IFS(BM7="No Evidence",10, BM7="Unknown",3, BM7="Likely",0, BM7="Confirmed",-10, TRUE,3) + IFERROR(_xlfn.XLOOKUP(BP7,'Lookup Tables'!$J$21:$J$24,'Lookup Tables'!$K$21:$K$24,0),0) ))} | CE7: {=MIN(100, MAX(0, IF(ISNUMBER(BV7)*AND(BV7>0), 10, 0) + _xlfn.IFS(BY7="Independently Verified",25, BY7="Yes",15, TRUE,0) + IFERROR(_xlfn.XLOOKUP(BZ7,'Lookup Tables'!$A$21:$A$24,'Lookup Tables'!$B$21:$B$24,0),0) + IFERROR(_xlfn.XLOOKUP(CA7,'Lookup Tables'!$D$21:$D$24,'Lookup Tables'!$E$21:$E$24,0),0) + _xlfn.IFS(ISNUMBER(CB7)*AND(CB7>=11),15, ISNUMBER(CB7)*AND(CB7>=6),10, ISNUMBER(CB7)*AND(CB7>=1),5, TRUE,0) + IFERROR(_xlfn.XLOOKUP(CC7,'Lookup Tables'!$G$21:$G$25,'Lookup Tables'!$H$21:$H$25,0),0) - IF(ISNUMBER(BW7)*AND(ISNUMBER(BV7))*AND(BW7>BV7), 20, 0) - IF(AND(BY7="Yes", ISNUMBER(BW7), BW7>60), 10, 0) ))} | CR7: =COUNTIF(CJ7:CQ7,"FAIL") | CS7: =COUNTIF(CJ7:CQ7,"PARTIAL") | CT7: =COUNTIF(CJ7:CQ7,"MISSING") | CU7: =MIN(100, CR7*15 + CS7*6 + CT7*3 + IFERROR(_xlfn.XLOOKUP(CW7,'Lookup Tables'!$M$21:$M$25,'Lookup Tables'!$N$21:$N$25,0),0) ) | CV7: =IFERROR( CHOOSE( MATCH("FAIL",CJ7:CQ7,0), "1-Specificity","2-Metric","3-Baseline","4-Target", "5-Time Horizon","6-Scope","7-Verification","8-Consistency" ), IFERROR( CHOOSE( MATCH("PARTIAL",CJ7:CQ7,0), "1-Specificity","2-Metric","3-Baseline","4-Target", "5-Time Horizon","6-Scope","7-Verification","8-Consistency" ), "No failures" ) ) | DA7: =IF(OR(CU7>=50,CW7="Material",CW7="Severe",AS7="Material",AS7="Severe",BF7="Material",BF7="Severe — Exclusion Trigger",AND(ISNUMBER(BS7),BS7<30)),"Yes","No") | DB7: =IF(OR(CR7>=6,AW7="Confirmed Violation",AX7="Confirmed Breach"),"Yes — Automatic",IF(CW7="Severe","Yes — Requires Captain Confirmation","No")) | DL7: =IF(OR(IFERROR(VALUE(LEFT(DF7,1)),99)<=2,IFERROR(VALUE(LEFT(DG7,1)),99)<=2),"Flagged","Clear") | DM7: =IF(OR(DA7="Yes",DB7<>"No",DH7="Unverified",DL7="Flagged"),"Yes","No") | DN7: {=MIN(100, IF(ISNUMBER(V7), _xlfn.IFS(V7>=3,25, V7=2,15, V7=1,5, TRUE,0), 0) + IFERROR(_xlfn.IFS(VALUE(LEFT(DF7,1))=5,25, VALUE(LEFT(DF7,1))=4,20, VALUE(LEFT(DF7,1))=3,15, VALUE(LEFT(DF7,1))=2,8, TRUE,0), 15) + IFERROR(_xlfn.IFS(VALUE(LEFT(DG7,1))=5,25, VALUE(LEFT(DG7,1))=4,20, VALUE(LEFT(DG7,1))=3,15, VALUE(LEFT(DG7,1))=2,8, TRUE,0), 15) + _xlfn.IFS(DH7="Fully Verified",25, DH7="Partially Verified",12, TRUE,0) )} | DO7: {=_xlfn.IFS( ISBLANK(AR7), "Insufficient Evidence", AND(AR7>=65, AJ7="Approved"), "Strong", AR7>=65, "Adequate", AR7>=40, "Adequate", AR7>=20, "Weak", TRUE, "Insufficient Evidence" )} | DP7: {=_xlfn.IFS( ISBLANK(BS7), "Insufficient Evidence", BS7>=65, "Strong", BS7>=40, "Adequate", BS7>=20, "Weak", TRUE, "Insufficient Evidence" )} | DQ7: {=_xlfn.IFS( ISBLANK(BE7), "Insufficient Evidence", OR(AW7="Confirmed Violation", AX7="Confirmed Breach"), "Severe — Hard Trigger", BE7>=65, "Strong", BE7>=40, "Adequate", BE7>=20, "Weak", TRUE, "Insufficient Evidence" )} | DR7: {=_xlfn.IFS( ISBLANK(CU7), "Insufficient Evidence", CU7<=20, "Low Risk", CU7<=50, "Moderate Risk", CU7<=75, "High Risk", TRUE, "Very High Risk" )} | DS7: {=_xlfn.IFS( ISBLANK(CE7), "Insufficient Evidence", AND(ISNUMBER(BW7),ISNUMBER(BV7),BW7>BV7), "Overclaiming Risk", CE7>=65, "Strong", CE7>=40, "Adequate", TRUE, "Weak" )} | DT7: =IF(DB7="Yes — Automatic",0,ROUND((IF(ISNUMBER(AR7),AR7,0)*0.3+IF(ISNUMBER(BS7),BS7,0)*0.2+IF(ISNUMBER(BE7),BE7,0)*0.2+IF(ISNUMBER(CE7),CE7,0)*0.15+(100-IF(ISNUMBER(CU7),CU7,50))*0.15)*IF(DN7>=75,1,IF(DN7>=50,0.9,IF(DN7>=25,0.75,0.6))),1)) | DU7: {=_xlfn.IFS( DV7="Upgraded to Clear", "Clear", DV7="Downgraded to Watchlist", "Watchlist", DV7="Downgraded to Exclusion", "Exclusion Risk", DB7="Yes — Automatic", "Exclusion Risk", OR(AW7="Confirmed Violation", AX7="Confirmed Breach"), "Exclusion Risk", OR(V7=0, ISBLANK(V7), DN7<20), "Insufficient Evidence", AND(DT7>=65, DA7="No", DB7="No"), "Clear", OR(DT7>=40, DA7="Yes"), "Watchlist", TRUE, "Exclusion Risk" )} | DW7: {=_xlfn.IFS( DU7="Exclusion Risk", "Exclude — Hard Trigger", DU7="Insufficient Evidence", "Watchlist — Further Evidence Needed", DU7="Watchlist", "Watchlist — Further Evidence Needed", AND(DU7="Clear", DT7>=80), "Include — No Conditions", DU7="Clear", "Include — Monitor", TRUE, "Watchlist — Further Evidence Needed" )} | EB7: =IF(OR(V7=0, ISBLANK(V7)), "MISSING — No sources reviewed", "") | EC7: =IF(AND(NOT(ISBLANK(DC7)), ISBLANK(DE7)), "PAGE REF MISSING", "") | ED7: =COUNTIF(DH7:DH56,"Fully Verified") | EE7: =IFERROR(COUNTIF(DH7:DH56,"Fully Verified")/COUNTA(B7:B56),0) | EF7: =COUNTIFS(DU7:DU56,"Clear",DH7:DH56,"Fully Verified")
A8: SBM Offshore NV | B8: IHCB | C8: NL0000360618 | F8: =IF(ISBLANK('Universe Tracker'!F4),"",'Universe Tracker'!F4) | G8: =IF(ISBLANK('Universe Tracker'!G4),"",'Universe Tracker'!G4) | J8: =IF(ISBLANK(B8),"",B8&"_"&C8) | O8: Yes | P8: Yes | Y8: =IF(AND(V8>=2,K8="Yes",L8="Yes"),"Sufficient",IF(AND(V8>=1,OR(K8="Yes",L8="Yes")),"Thin","Insufficient")) | AJ8: Not in SBTi database (checked 2026-05-21) | AR8: {=MIN(100, MAX(0, IFERROR(_xlfn.XLOOKUP(AJ8,'Lookup Tables'!$A$2:$A$7,'Lookup Tables'!$B$2:$B$7,0),0) + IF(Z8="Yes", IF(IFERROR(_xlfn.XLOOKUP(AJ8,'Lookup Tables'!$A$2:$A$7,'Lookup Tables'!$B$2:$B$7,0),0)<20, 5, 0), 0) + _xlfn.IFS(AB8="Yes", IF(ISNUMBER(AC8)*AND(AC8<=2030),15,10), AB8="Long-term Only", 5, AB8="No", 0, TRUE, 0) + _xlfn.IFS(AF8="Full",10, AF8="Partial",5, AF8="Scope 2 Only",3, TRUE,0) + _xlfn.IFS(AG8="Yes", IF(ISNUMBER(AH8)*AND(AH8>=5),10,6), AG8="Partial",4, TRUE,0) + _xlfn.IFS(AI8="Yes",5, AI8="Partial (material categories only)",3, TRUE,0) + _xlfn.IFS(AL8="Yes — Detailed",10, AL8="Yes — High Level",5, TRUE,0) + _xlfn.IFS(AM8="Yes — Quantified",15, AM8="Yes — Directional Only",7, TRUE,0) + _xlfn.IFS(AP8="Formal",5, AP8="Referenced",2, TRUE,0) + _xlfn.IFS(AQ8="No Issues Found",5, AQ8="Concern Identified",-5, AQ8="Severe Contradiction",-15, TRUE,0) + _xlfn.IFS(BC8="Reasonable Assurance",5, BC8="Limited Assurance",3, TRUE,0) - IF(AND(Z8="Yes", AI8="No"), 10, 0) - IF(AND(Z8="Yes", AM8="No"), 10, 0) ))} | BE8: {=MIN(100, MAX(0, IFERROR(_xlfn.XLOOKUP(AT8,'Lookup Tables'!$D$2:$D$6,'Lookup Tables'!$E$2:$E$6,0),0) + IFERROR(_xlfn.XLOOKUP(AV8,'Lookup Tables'!$G$2:$G$5,'Lookup Tables'!$H$2:$H$5,0),0) + IFERROR(_xlfn.XLOOKUP(AW8,'Lookup Tables'!$J$2:$J$5,'Lookup Tables'!$K$2:$K$5,0),0) + _xlfn.IFS(AX8="No Issues",10, AX8="Complaint Filed",3, AX8="Confirmed Breach",-15, TRUE,0) + IFERROR(_xlfn.XLOOKUP(AY8,'Lookup Tables'!$M$2:$M$6,'Lookup Tables'!$N$2:$N$6,0),0) + IFERROR(_xlfn.XLOOKUP(AZ8,'Lookup Tables'!$P$2:$P$6,'Lookup Tables'!$Q$2:$Q$6,0),0) + _xlfn.IFS(BA8="Formal Board Committee",5, BA8="Board Oversight Mentioned",2, TRUE,0) + _xlfn.IFS(BB8="Yes — Quantified Targets",5, BB8="Yes — Discretionary Only",2, TRUE,0) + _xlfn.IFS(BC8="Reasonable Assurance",5, BC8="Limited Assurance",3, BC8="Management Review Only",1, TRUE,0) ))} | BS8: {=MIN(100, MAX(0, IFERROR(_xlfn.XLOOKUP(BG8,'Lookup Tables'!$A$11:$A$16,'Lookup Tables'!$B$11:$B$16,0),0) + IFERROR(_xlfn.XLOOKUP(BR8,'Lookup Tables'!$M$11:$M$14,'Lookup Tables'!$N$11:$N$14,0),0) + IFERROR(_xlfn.XLOOKUP(BQ8,'Lookup Tables'!$J$11:$J$15,'Lookup Tables'!$K$11:$K$15,0),0) + IFERROR(_xlfn.XLOOKUP(BH8,'Lookup Tables'!$D$11:$D$15,'Lookup Tables'!$E$11:$E$15,0),0) + IFERROR(_xlfn.XLOOKUP(BJ8,'Lookup Tables'!$G$11:$G$16,'Lookup Tables'!$H$11:$H$16,0),0) + IFERROR(_xlfn.XLOOKUP(BN8,'Lookup Tables'!$P$11:$P$15,'Lookup Tables'!$Q$11:$Q$15,0),0) + _xlfn.IFS(BM8="No Evidence",10, BM8="Unknown",3, BM8="Likely",0, BM8="Confirmed",-10, TRUE,3) + IFERROR(_xlfn.XLOOKUP(BP8,'Lookup Tables'!$J$21:$J$24,'Lookup Tables'!$K$21:$K$24,0),0) ))} | CE8: {=MIN(100, MAX(0, IF(ISNUMBER(BV8)*AND(BV8>0), 10, 0) + _xlfn.IFS(BY8="Independently Verified",25, BY8="Yes",15, TRUE,0) + IFERROR(_xlfn.XLOOKUP(BZ8,'Lookup Tables'!$A$21:$A$24,'Lookup Tables'!$B$21:$B$24,0),0) + IFERROR(_xlfn.XLOOKUP(CA8,'Lookup Tables'!$D$21:$D$24,'Lookup Tables'!$E$21:$E$24,0),0) + _xlfn.IFS(ISNUMBER(CB8)*AND(CB8>=11),15, ISNUMBER(CB8)*AND(CB8>=6),10, ISNUMBER(CB8)*AND(CB8>=1),5, TRUE,0) + IFERROR(_xlfn.XLOOKUP(CC8,'Lookup Tables'!$G$21:$G$25,'Lookup Tables'!$H$21:$H$25,0),0) - IF(ISNUMBER(BW8)*AND(ISNUMBER(BV8))*AND(BW8>BV8), 20, 0) - IF(AND(BY8="Yes", ISNUMBER(BW8), BW8>60), 10, 0) ))} | CG8: Including the use of certified climate projects to compensate any residual scope 1 and 2 emissions | CH8: SBM-Offshore-Annual-Report-2025.pdf | CI8: 12 | CJ8: PARTIAL | CK8: PASS | CL8: PASS | CM8: PARTIAL | CN8: PASS | CO8: PASS | CP8: PARTIAL | CQ8: PARTIAL | CR8: =COUNTIF(CJ8:CQ8,"FAIL") | CS8: =COUNTIF(CJ8:CQ8,"PARTIAL") | CT8: =COUNTIF(CJ8:CQ8,"MISSING") | CU8: =MIN(100, CR8*15 + CS8*6 + CT8*3 + IFERROR(_xlfn.XLOOKUP(CW8,'Lookup Tables'!$M$21:$M$25,'Lookup Tables'!$N$21:$N$25,0),0) ) | CV8: =IFERROR( CHOOSE( MATCH("FAIL",CJ8:CQ8,0), "1-Specificity","2-Metric","3-Baseline","4-Target", "5-Time Horizon","6-Scope","7-Verification","8-Consistency" ), IFERROR( CHOOSE( MATCH("PARTIAL",CJ8:CQ8,0), "1-Specificity","2-Metric","3-Baseline","4-Target", "5-Time Horizon","6-Scope","7-Verification","8-Consistency" ), "No failures" ) ) | DA8: =IF(OR(CU8>=50,CW8="Material",CW8="Severe",AS8="Material",AS8="Severe",BF8="Material",BF8="Severe — Exclusion Trigger",AND(ISNUMBER(BS8),BS8<30)),"Yes","No") | DB8: =IF(OR(CR8>=6,AW8="Confirmed Violation",AX8="Confirmed Breach"),"Yes — Automatic",IF(CW8="Severe","Yes — Requires Captain Confirmation","No")) | DC8: Including the use of certified climate projects to compensate any residual scope 1 and 2 emissions | DD8: SBM-Offshore-Annual-Report-2025.pdf | DE8: 12 | DF8: 4 | DG8: 4 | DH8: PENDING | DL8: =IF(OR(IFERROR(VALUE(LEFT(DF8,1)),99)<=2,IFERROR(VALUE(LEFT(DG8,1)),99)<=2),"Flagged","Clear") | DM8: =IF(OR(DA8="Yes",DB8<>"No",DH8="Unverified",DL8="Flagged"),"Yes","No") | DN8: {=MIN(100, IF(ISNUMBER(V8), _xlfn.IFS(V8>=3,25, V8=2,15, V8=1,5, TRUE,0), 0) + IFERROR(_xlfn.IFS(VALUE(LEFT(DF8,1))=5,25, VALUE(LEFT(DF8,1))=4,20, VALUE(LEFT(DF8,1))=3,15, VALUE(LEFT(DF8,1))=2,8, TRUE,0), 15) + IFERROR(_xlfn.IFS(VALUE(LEFT(DG8,1))=5,25, VALUE(LEFT(DG8,1))=4,20, VALUE(LEFT(DG8,1))=3,15, VALUE(LEFT(DG8,1))=2,8, TRUE,0), 15) + _xlfn.IFS(DH8="Fully Verified",25, DH8="Partially Verified",12, TRUE,0) )} | DO8: {=_xlfn.IFS( ISBLANK(AR8), "Insufficient Evidence", AND(AR8>=65, AJ8="Approved"), "Strong", AR8>=65, "Adequate", AR8>=40, "Adequate", AR8>=20, "Weak", TRUE, "Insufficient Evidence" )} | DP8: {=_xlfn.IFS( ISBLANK(BS8), "Insufficient Evidence", BS8>=65, "Strong", BS8>=40, "Adequate", BS8>=20, "Weak", TRUE, "Insufficient Evidence" )} | DQ8: {=_xlfn.IFS( ISBLANK(BE8), "Insufficient Evidence", OR(AW8="Confirmed Violation", AX8="Confirmed Breach"), "Severe — Hard Trigger", BE8>=65, "Strong", BE8>=40, "Adequate", BE8>=20, "Weak", TRUE, "Insufficient Evidence" )} | DR8: {=_xlfn.IFS( ISBLANK(CU8), "Insufficient Evidence", CU8<=20, "Low Risk", CU8<=50, "Moderate Risk", CU8<=75, "High Risk", TRUE, "Very High Risk" )} | DS8: {=_xlfn.IFS( ISBLANK(CE8), "Insufficient Evidence", AND(ISNUMBER(BW8),ISNUMBER(BV8),BW8>BV8), "Overclaiming Risk", CE8>=65, "Strong", CE8>=40, "Adequate", TRUE, "Weak" )} | DT8: =IF(DB8="Yes — Automatic",0,ROUND((IF(ISNUMBER(AR8),AR8,0)*0.3+IF(ISNUMBER(BS8),BS8,0)*0.2+IF(ISNUMBER(BE8),BE8,0)*0.2+IF(ISNUMBER(CE8),CE8,0)*0.15+(100-IF(ISNUMBER(CU8),CU8,50))*0.15)*IF(DN8>=75,1,IF(DN8>=50,0.9,IF(DN8>=25,0.75,0.6))),1)) | DU8: {=_xlfn.IFS( DV8="Upgraded to Clear", "Clear", DV8="Downgraded to Watchlist", "Watchlist", DV8="Downgraded to Exclusion", "Exclusion Risk", DB8="Yes — Automatic", "Exclusion Risk", OR(AW8="Confirmed Violation", AX8="Confirmed Breach"), "Exclusion Risk", OR(V8=0, ISBLANK(V8), DN8<20), "Insufficient Evidence", AND(DT8>=65, DA8="No", DB8="No"), "Clear", OR(DT8>=40, DA8="Yes"), "Watchlist", TRUE, "Exclusion Risk" )} | DW8: {=_xlfn.IFS( DU8="Exclusion Risk", "Exclude — Hard Trigger", DU8="Insufficient Evidence", "Watchlist — Further Evidence Needed", DU8="Watchlist", "Watchlist — Further Evidence Needed", AND(DU8="Clear", DT8>=80), "Include — No Conditions", DU8="Clear", "Include — Monitor", TRUE, "Watchlist — Further Evidence Needed" )} | DX8: Main claim: "Including the use of certified climate projects to compensate any residual scope 1 and 2 emissions" (SBM-Offshore-Annual-Report-2025.pdf, p12). SBTi: no validated target in the SBTi database. 8-Test: 4 PARTIAL, 0 FAIL, 0 MISSING -> PASS. Offshore-energy contractor. Disclosure is structured (2016 base year, intermediary 2030 targets, ISAE limited assurance) but four MED flags reflect an offset-reliant near-term 'climate neutral' claim, SBTi-guideline-based (not... | EB8: =IF(OR(V8=0, ISBLANK(V8)), "MISSING — No sources reviewed", "") | EC8: =IF(AND(NOT(ISBLANK(DC8)), ISBLANK(DE8)), "PAGE REF MISSING", "")
A9: Drax Group PLC | B9: D9F2 | C9: =IF(ISBLANK('Universe Tracker'!D5),"",'Universe Tracker'!D5) | F9: =IF(ISBLANK('Universe Tracker'!F5),"",'Universe Tracker'!F5) | G9: =IF(ISBLANK('Universe Tracker'!G5),"",'Universe Tracker'!G5) | J9: =IF(ISBLANK(B9),"",B9&"_"&C9) | Y9: =IF(AND(V9>=2,K9="Yes",L9="Yes"),"Sufficient",IF(AND(V9>=1,OR(K9="Yes",L9="Yes")),"Thin","Insufficient")) | AR9: {=MIN(100, MAX(0, IFERROR(_xlfn.XLOOKUP(AJ9,'Lookup Tables'!$A$2:$A$7,'Lookup Tables'!$B$2:$B$7,0),0) + IF(Z9="Yes", IF(IFERROR(_xlfn.XLOOKUP(AJ9,'Lookup Tables'!$A$2:$A$7,'Lookup Tables'!$B$2:$B$7,0),0)<20, 5, 0), 0) + _xlfn.IFS(AB9="Yes", IF(ISNUMBER(AC9)*AND(AC9<=2030),15,10), AB9="Long-term Only", 5, AB9="No", 0, TRUE, 0) + _xlfn.IFS(AF9="Full",10, AF9="Partial",5, AF9="Scope 2 Only",3, TRUE,0) + _xlfn.IFS(AG9="Yes", IF(ISNUMBER(AH9)*AND(AH9>=5),10,6), AG9="Partial",4, TRUE,0) + _xlfn.IFS(AI9="Yes",5, AI9="Partial (material categories only)",3, TRUE,0) + _xlfn.IFS(AL9="Yes — Detailed",10, AL9="Yes — High Level",5, TRUE,0) + _xlfn.IFS(AM9="Yes — Quantified",15, AM9="Yes — Directional Only",7, TRUE,0) + _xlfn.IFS(AP9="Formal",5, AP9="Referenced",2, TRUE,0) + _xlfn.IFS(AQ9="No Issues Found",5, AQ9="Concern Identified",-5, AQ9="Severe Contradiction",-15, TRUE,0) + _xlfn.IFS(BC9="Reasonable Assurance",5, BC9="Limited Assurance",3, TRUE,0) - IF(AND(Z9="Yes", AI9="No"), 10, 0) - IF(AND(Z9="Yes", AM9="No"), 10, 0) ))} | BE9: {=MIN(100, MAX(0, IFERROR(_xlfn.XLOOKUP(AT9,'Lookup Tables'!$D$2:$D$6,'Lookup Tables'!$E$2:$E$6,0),0) + IFERROR(_xlfn.XLOOKUP(AV9,'Lookup Tables'!$G$2:$G$5,'Lookup Tables'!$H$2:$H$5,0),0) + IFERROR(_xlfn.XLOOKUP(AW9,'Lookup Tables'!$J$2:$J$5,'Lookup Tables'!$K$2:$K$5,0),0) + _xlfn.IFS(AX9="No Issues",10, AX9="Complaint Filed",3, AX9="Confirmed Breach",-15, TRUE,0) + IFERROR(_xlfn.XLOOKUP(AY9,'Lookup Tables'!$M$2:$M$6,'Lookup Tables'!$N$2:$N$6,0),0) + IFERROR(_xlfn.XLOOKUP(AZ9,'Lookup Tables'!$P$2:$P$6,'Lookup Tables'!$Q$2:$Q$6,0),0) + _xlfn.IFS(BA9="Formal Board Committee",5, BA9="Board Oversight Mentioned",2, TRUE,0) + _xlfn.IFS(BB9="Yes — Quantified Targets",5, BB9="Yes — Discretionary Only",2, TRUE,0) + _xlfn.IFS(BC9="Reasonable Assurance",5, BC9="Limited Assurance",3, BC9="Management Review Only",1, TRUE,0) ))} | BS9: {=MIN(100, MAX(0, IFERROR(_xlfn.XLOOKUP(BG9,'Lookup Tables'!$A$11:$A$16,'Lookup Tables'!$B$11:$B$16,0),0) + IFERROR(_xlfn.XLOOKUP(BR9,'Lookup Tables'!$M$11:$M$14,'Lookup Tables'!$N$11:$N$14,0),0) + IFERROR(_xlfn.XLOOKUP(BQ9,'Lookup Tables'!$J$11:$J$15,'Lookup Tables'!$K$11:$K$15,0),0) + IFERROR(_xlfn.XLOOKUP(BH9,'Lookup Tables'!$D$11:$D$15,'Lookup Tables'!$E$11:$E$15,0),0) + IFERROR(_xlfn.XLOOKUP(BJ9,'Lookup Tables'!$G$11:$G$16,'Lookup Tables'!$H$11:$H$16,0),0) + IFERROR(_xlfn.XLOOKUP(BN9,'Lookup Tables'!$P$11:$P$15,'Lookup Tables'!$Q$11:$Q$15,0),0) + _xlfn.IFS(BM9="No Evidence",10, BM9="Unknown",3, BM9="Likely",0, BM9="Confirmed",-10, TRUE,3) + IFERROR(_xlfn.XLOOKUP(BP9,'Lookup Tables'!$J$21:$J$24,'Lookup Tables'!$K$21:$K$24,0),0) ))} | CE9: {=MIN(100, MAX(0, IF(ISNUMBER(BV9)*AND(BV9>0), 10, 0) + _xlfn.IFS(BY9="Independently Verified",25, BY9="Yes",15, TRUE,0) + IFERROR(_xlfn.XLOOKUP(BZ9,'Lookup Tables'!$A$21:$A$24,'Lookup Tables'!$B$21:$B$24,0),0) + IFERROR(_xlfn.XLOOKUP(CA9,'Lookup Tables'!$D$21:$D$24,'Lookup Tables'!$E$21:$E$24,0),0) + _xlfn.IFS(ISNUMBER(CB9)*AND(CB9>=11),15, ISNUMBER(CB9)*AND(CB9>=6),10, ISNUMBER(CB9)*AND(CB9>=1),5, TRUE,0) + IFERROR(_xlfn.XLOOKUP(CC9,'Lookup Tables'!$G$21:$G$25,'Lookup Tables'!$H$21:$H$25,0),0) - IF(ISNUMBER(BW9)*AND(ISNUMBER(BV9))*AND(BW9>BV9), 20, 0) - IF(AND(BY9="Yes", ISNUMBER(BW9), BW9>60), 10, 0) ))} | CR9: =COUNTIF(CJ9:CQ9,"FAIL") | CS9: =COUNTIF(CJ9:CQ9,"PARTIAL") | CT9: =COUNTIF(CJ9:CQ9,"MISSING") | CU9: =MIN(100, CR9*15 + CS9*6 + CT9*3 + IFERROR(_xlfn.XLOOKUP(CW9,'Lookup Tables'!$M$21:$M$25,'Lookup Tables'!$N$21:$N$25,0),0) ) | CV9: =IFERROR( CHOOSE( MATCH("FAIL",CJ9:CQ9,0), "1-Specificity","2-Metric","3-Baseline","4-Target", "5-Time Horizon","6-Scope","7-Verification","8-Consistency" ), IFERROR( CHOOSE( MATCH("PARTIAL",CJ9:CQ9,0), "1-Specificity","2-Metric","3-Baseline","4-Target", "5-Time Horizon","6-Scope","7-Verification","8-Consistency" ), "No failures" ) ) | DA9: =IF(OR(CU9>=50,CW9="Material",CW9="Severe",AS9="Material",AS9="Severe",BF9="Material",BF9="Severe — Exclusion Trigger",AND(ISNUMBER(BS9),BS9<30)),"Yes","No") | DB9: =IF(OR(CR9>=6,AW9="Confirmed Violation",AX9="Confirmed Breach"),"Yes — Automatic",IF(CW9="Severe","Yes — Requires Captain Confirmation","No")) | DL9: =IF(OR(IFERROR(VALUE(LEFT(DF9,1)),99)<=2,IFERROR(VALUE(LEFT(DG9,1)),99)<=2),"Flagged","Clear") | DM9: =IF(OR(DA9="Yes",DB9<>"No",DH9="Unverified",DL9="Flagged"),"Yes","No") | DN9: {=MIN(100, IF(ISNUMBER(V9), _xlfn.IFS(V9>=3,25, V9=2,15, V9=1,5, TRUE,0), 0) + IFERROR(_xlfn.IFS(VALUE(LEFT(DF9,1))=5,25, VALUE(LEFT(DF9,1))=4,20, VALUE(LEFT(DF9,1))=3,15, VALUE(LEFT(DF9,1))=2,8, TRUE,0), 15) + IFERROR(_xlfn.IFS(VALUE(LEFT(DG9,1))=5,25, VALUE(LEFT(DG9,1))=4,20, VALUE(LEFT(DG9,1))=3,15, VALUE(LEFT(DG9,1))=2,8, TRUE,0), 15) + _xlfn.IFS(DH9="Fully Verified",25, DH9="Partially Verified",12, TRUE,0) )} | DO9: {=_xlfn.IFS( ISBLANK(AR9), "Insufficient Evidence", AND(AR9>=65, AJ9="Approved"), "Strong", AR9>=65, "Adequate", AR9>=40, "Adequate", AR9>=20, "Weak", TRUE, "Insufficient Evidence" )} | DP9: {=_xlfn.IFS( ISBLANK(BS9), "Insufficient Evidence", BS9>=65, "Strong", BS9>=40, "Adequate", BS9>=20, "Weak", TRUE, "Insufficient Evidence" )} | DQ9: {=_xlfn.IFS( ISBLANK(BE9), "Insufficient Evidence", OR(AW9="Confirmed Violation", AX9="Confirmed Breach"), "Severe — Hard Trigger", BE9>=65, "Strong", BE9>=40, "Adequate", BE9>=20, "Weak", TRUE, "Insufficient Evidence" )} | DR9: {=_xlfn.IFS( ISBLANK(CU9), "Insufficient Evidence", CU9<=20, "Low Risk", CU9<=50, "Moderate Risk", CU9<=75, "High Risk", TRUE, "Very High Risk" )} | DS9: {=_xlfn.IFS( ISBLANK(CE9), "Insufficient Evidence", AND(ISNUMBER(BW9),ISNUMBER(BV9),BW9>BV9), "Overclaiming Risk", CE9>=65, "Strong", CE9>=40, "Adequate", TRUE, "Weak" )} | DT9: =IF(DB9="Yes — Automatic",0,ROUND((IF(ISNUMBER(AR9),AR9,0)*0.3+IF(ISNUMBER(BS9),BS9,0)*0.2+IF(ISNUMBER(BE9),BE9,0)*0.2+IF(ISNUMBER(CE9),CE9,0)*0.15+(100-IF(ISNUMBER(CU9),CU9,50))*0.15)*IF(DN9>=75,1,IF(DN9>=50,0.9,IF(DN9>=25,0.75,0.6))),1)) | DU9: {=_xlfn.IFS( DV9="Upgraded to Clear", "Clear", DV9="Downgraded to Watchlist", "Watchlist", DV9="Downgraded to Exclusion", "Exclusion Risk", DB9="Yes — Automatic", "Exclusion Risk", OR(AW9="Confirmed Violation", AX9="Confirmed Breach"), "Exclusion Risk", OR(V9=0, ISBLANK(V9), DN9<20), "Insufficient Evidence", AND(DT9>=65, DA9="No", DB9="No"), "Clear", OR(DT9>=40, DA9="Yes"), "Watchlist", TRUE, "Exclusion Risk" )} | DW9: {=_xlfn.IFS( DU9="Exclusion Risk", "Exclude — Hard Trigger", DU9="Insufficient Evidence", "Watchlist — Further Evidence Needed", DU9="Watchlist", "Watchlist — Further Evidence Needed", AND(DU9="Clear", DT9>=80), "Include — No Conditions", DU9="Clear", "Include — Monitor", TRUE, "Watchlist — Further Evidence Needed" )} | EB9: =IF(OR(V9=0, ISBLANK(V9)), "MISSING — No sources reviewed", "") | EC9: =IF(AND(NOT(ISBLANK(DC9)), ISBLANK(DE9)), "PAGE REF MISSING", "")
A10: SSAB AB | B10: SKWA | C10: =IF(ISBLANK('Universe Tracker'!D6),"",'Universe Tracker'!D6) | F10: =IF(ISBLANK('Universe Tracker'!F6),"",'Universe Tracker'!F6) | G10: =IF(ISBLANK('Universe Tracker'!G6),"",'Universe Tracker'!G6) | J10: =IF(ISBLANK(B10),"",B10&"_"&C10) | Y10: =IF(AND(V10>=2,K10="Yes",L10="Yes"),"Sufficient",IF(AND(V10>=1,OR(K10="Yes",L10="Yes")),"Thin","Insufficient")) | AR10: {=MIN(100, MAX(0, IFERROR(_xlfn.XLOOKUP(AJ10,'Lookup Tables'!$A$2:$A$7,'Lookup Tables'!$B$2:$B$7,0),0) + IF(Z10="Yes", IF(IFERROR(_xlfn.XLOOKUP(AJ10,'Lookup Tables'!$A$2:$A$7,'Lookup Tables'!$B$2:$B$7,0),0)<20, 5, 0), 0) + _xlfn.IFS(AB10="Yes", IF(ISNUMBER(AC10)*AND(AC10<=2030),15,10), AB10="Long-term Only", 5, AB10="No", 0, TRUE, 0) + _xlfn.IFS(AF10="Full",10, AF10="Partial",5, AF10="Scope 2 Only",3, TRUE,0) + _xlfn.IFS(AG10="Yes", IF(ISNUMBER(AH10)*AND(AH10>=5),10,6), AG10="Partial",4, TRUE,0) + _xlfn.IFS(AI10="Yes",5, AI10="Partial (material categories only)",3, TRUE,0) + _xlfn.IFS(AL10="Yes — Detailed",10, AL10="Yes — High Level",5, TRUE,0) + _xlfn.IFS(AM10="Yes — Quantified",15, AM10="Yes — Directional Only",7, TRUE,0) + _xlfn.IFS(AP10="Formal",5, AP10="Referenced",2, TRUE,0) + _xlfn.IFS(AQ10="No Issues Found",5, AQ10="Concern Identified",-5, AQ10="Severe Contradiction",-15, TRUE,0) + _xlfn.IFS(BC10="Reasonable Assurance",5, BC10="Limited Assurance",3, TRUE,0) - IF(AND(Z10="Yes", AI10="No"), 10, 0) - IF(AND(Z10="Yes", AM10="No"), 10, 0) ))} | BE10: {=MIN(100, MAX(0, IFERROR(_xlfn.XLOOKUP(AT10,'Lookup Tables'!$D$2:$D$6,'Lookup Tables'!$E$2:$E$6,0),0) + IFERROR(_xlfn.XLOOKUP(AV10,'Lookup Tables'!$G$2:$G$5,'Lookup Tables'!$H$2:$H$5,0),0) + IFERROR(_xlfn.XLOOKUP(AW10,'Lookup Tables'!$J$2:$J$5,'Lookup Tables'!$K$2:$K$5,0),0) + _xlfn.IFS(AX10="No Issues",10, AX10="Complaint Filed",3, AX10="Confirmed Breach",-15, TRUE,0) + IFERROR(_xlfn.XLOOKUP(AY10,'Lookup Tables'!$M$2:$M$6,'Lookup Tables'!$N$2:$N$6,0),0) + IFERROR(_xlfn.XLOOKUP(AZ10,'Lookup Tables'!$P$2:$P$6,'Lookup Tables'!$Q$2:$Q$6,0),0) + _xlfn.IFS(BA10="Formal Board Committee",5, BA10="Board Oversight Mentioned",2, TRUE,0) + _xlfn.IFS(BB10="Yes — Quantified Targets",5, BB10="Yes — Discretionary Only",2, TRUE,0) + _xlfn.IFS(BC10="Reasonable Assurance",5, BC10="Limited Assurance",3, BC10="Management Review Only",1, TRUE,0) ))} | BS10: {=MIN(100, MAX(0, IFERROR(_xlfn.XLOOKUP(BG10,'Lookup Tables'!$A$11:$A$16,'Lookup Tables'!$B$11:$B$16,0),0) + IFERROR(_xlfn.XLOOKUP(BR10,'Lookup Tables'!$M$11:$M$14,'Lookup Tables'!$N$11:$N$14,0),0) + IFERROR(_xlfn.XLOOKUP(BQ10,'Lookup Tables'!$J$11:$J$15,'Lookup Tables'!$K$11:$K$15,0),0) + IFERROR(_xlfn.XLOOKUP(BH10,'Lookup Tables'!$D$11:$D$15,'Lookup Tables'!$E$11:$E$15,0),0) + IFERROR(_xlfn.XLOOKUP(BJ10,'Lookup Tables'!$G$11:$G$16,'Lookup Tables'!$H$11:$H$16,0),0) + IFERROR(_xlfn.XLOOKUP(BN10,'Lookup Tables'!$P$11:$P$15,'Lookup Tables'!$Q$11:$Q$15,0),0) + _xlfn.IFS(BM10="No Evidence",10, BM10="Unknown",3, BM10="Likely",0, BM10="Confirmed",-10, TRUE,3) + IFERROR(_xlfn.XLOOKUP(BP10,'Lookup Tables'!$J$21:$J$24,'Lookup Tables'!$K$21:$K$24,0),0) ))} | CE10: {=MIN(100, MAX(0, IF(ISNUMBER(BV10)*AND(BV10>0), 10, 0) + _xlfn.IFS(BY10="Independently Verified",25, BY10="Yes",15, TRUE,0) + IFERROR(_xlfn.XLOOKUP(BZ10,'Lookup Tables'!$A$21:$A$24,'Lookup Tables'!$B$21:$B$24,0),0) + IFERROR(_xlfn.XLOOKUP(CA10,'Lookup Tables'!$D$21:$D$24,'Lookup Tables'!$E$21:$E$24,0),0) + _xlfn.IFS(ISNUMBER(CB10)*AND(CB10>=11),15, ISNUMBER(CB10)*AND(CB10>=6),10, ISNUMBER(CB10)*AND(CB10>=1),5, TRUE,0) + IFERROR(_xlfn.XLOOKUP(CC10,'Lookup Tables'!$G$21:$G$25,'Lookup Tables'!$H$21:$H$25,0),0) - IF(ISNUMBER(BW10)*AND(ISNUMBER(BV10))*AND(BW10>BV10), 20, 0) - IF(AND(BY10="Yes", ISNUMBER(BW10), BW10>60), 10, 0) ))} | CR10: =COUNTIF(CJ10:CQ10,"FAIL") | CS10: =COUNTIF(CJ10:CQ10,"PARTIAL") | CT10: =COUNTIF(CJ10:CQ10,"MISSING") | CU10: =MIN(100, CR10*15 + CS10*6 + CT10*3 + IFERROR(_xlfn.XLOOKUP(CW10,'Lookup Tables'!$M$21:$M$25,'Lookup Tables'!$N$21:$N$25,0),0) ) | CV10: =IFERROR( CHOOSE( MATCH("FAIL",CJ10:CQ10,0), "1-Specificity","2-Metric","3-Baseline","4-Target", "5-Time Horizon","6-Scope","7-Verification","8-Consistency" ), IFERROR( CHOOSE( MATCH("PARTIAL",CJ10:CQ10,0), "1-Specificity","2-Metric","3-Baseline","4-Target", "5-Time Horizon","6-Scope","7-Verification","8-Consistency" ), "No failures" ) ) | DA10: =IF(OR(CU10>=50,CW10="Material",CW10="Severe",AS10="Material",AS10="Severe",BF10="Material",BF10="Severe — Exclusion Trigger",AND(ISNUMBER(BS10),BS10<30)),"Yes","No") | DB10: =IF(OR(CR10>=6,AW10="Confirmed Violation",AX10="Confirmed Breach"),"Yes — Automatic",IF(CW10="Severe","Yes — Requires Captain Confirmation","No")) | DL10: =IF(OR(IFERROR(VALUE(LEFT(DF10,1)),99)<=2,IFERROR(VALUE(LEFT(DG10,1)),99)<=2),"Flagged","Clear") | DM10: =IF(OR(DA10="Yes",DB10<>"No",DH10="Unverified",DL10="Flagged"),"Yes","No") | DN10: {=MIN(100, IF(ISNUMBER(V10), _xlfn.IFS(V10>=3,25, V10=2,15, V10=1,5, TRUE,0), 0) + IFERROR(_xlfn.IFS(VALUE(LEFT(DF10,1))=5,25, VALUE(LEFT(DF10,1))=4,20, VALUE(LEFT(DF10,1))=3,15, VALUE(LEFT(DF10,1))=2,8, TRUE,0), 15) + IFERROR(_xlfn.IFS(VALUE(LEFT(DG10,1))=5,25, VALUE(LEFT(DG10,1))=4,20, VALUE(LEFT(DG10,1))=3,15, VALUE(LEFT(DG10,1))=2,8, TRUE,0), 15) + _xlfn.IFS(DH10="Fully Verified",25, DH10="Partially Verified",12, TRUE,0) )} | DO10: {=_xlfn.IFS( ISBLANK(AR10), "Insufficient Evidence", AND(AR10>=65, AJ10="Approved"), "Strong", AR10>=65, "Adequate", AR10>=40, "Adequate", AR10>=20, "Weak", TRUE, "Insufficient Evidence" )} | DP10: {=_xlfn.IFS( ISBLANK(BS10), "Insufficient Evidence", BS10>=65, "Strong", BS10>=40, "Adequate", BS10>=20, "Weak", TRUE, "Insufficient Evidence" )} | DQ10: {=_xlfn.IFS( ISBLANK(BE10), "Insufficient Evidence", OR(AW10="Confirmed Violation", AX10="Confirmed Breach"), "Severe — Hard Trigger", BE10>=65, "Strong", BE10>=40, "Adequate", BE10>=20, "Weak", TRUE, "Insufficient Evidence" )} | DR10: {=_xlfn.IFS( ISBLANK(CU10), "Insufficient Evidence", CU10<=20, "Low Risk", CU10<=50, "Moderate Risk", CU10<=75, "High Risk", TRUE, "Very High Risk" )} | DS10: {=_xlfn.IFS( ISBLANK(CE10), "Insufficient Evidence", AND(ISNUMBER(BW10),ISNUMBER(BV10),BW10>BV10), "Overclaiming Risk", CE10>=65, "Strong", CE10>=40, "Adequate", TRUE, "Weak" )} | DT10: =IF(DB10="Yes — Automatic",0,ROUND((IF(ISNUMBER(AR10),AR10,0)*0.3+IF(ISNUMBER(BS10),BS10,0)*0.2+IF(ISNUMBER(BE10),BE10,0)*0.2+IF(ISNUMBER(CE10),CE10,0)*0.15+(100-IF(ISNUMBER(CU10),CU10,50))*0.15)*IF(DN10>=75,1,IF(DN10>=50,0.9,IF(DN10>=25,0.75,0.6))),1)) | DU10: {=_xlfn.IFS( DV10="Upgraded to Clear", "Clear", DV10="Downgraded to Watchlist", "Watchlist", DV10="Downgraded to Exclusion", "Exclusion Risk", DB10="Yes — Automatic", "Exclusion Risk", OR(AW10="Confirmed Violation", AX10="Confirmed Breach"), "Exclusion Risk", OR(V10=0, ISBLANK(V10), DN10<20), "Insufficient Evidence", AND(DT10>=65, DA10="No", DB10="No"), "Clear", OR(DT10>=40, DA10="Yes"), "Watchlist", TRUE, "Exclusion Risk" )} | DW10: {=_xlfn.IFS( DU10="Exclusion Risk", "Exclude — Hard Trigger", DU10="Insufficient Evidence", "Watchlist — Further Evidence Needed", DU10="Watchlist", "Watchlist — Further Evidence Needed", AND(DU10="Clear", DT10>=80), "Include — No Conditions", DU10="Clear", "Include — Monitor", TRUE, "Watchlist — Further Evidence Needed" )} | EB10: =IF(OR(V10=0, ISBLANK(V10)), "MISSING — No sources reviewed", "") | EC10: =IF(AND(NOT(ISBLANK(DC10)), ISBLANK(DE10)), "PAGE REF MISSING", "")
A11: Tenaris SA | B11: TW11 | C11: =IF(ISBLANK('Universe Tracker'!D7),"",'Universe Tracker'!D7) | F11: =IF(ISBLANK('Universe Tracker'!F7),"",'Universe Tracker'!F7) | G11: =IF(ISBLANK('Universe Tracker'!G7),"",'Universe Tracker'!G7) | J11: =IF(ISBLANK(B11),"",B11&"_"&C11) | Y11: =IF(AND(V11>=2,K11="Yes",L11="Yes"),"Sufficient",IF(AND(V11>=1,OR(K11="Yes",L11="Yes")),"Thin","Insufficient")) | AR11: {=MIN(100, MAX(0, IFERROR(_xlfn.XLOOKUP(AJ11,'Lookup Tables'!$A$2:$A$7,'Lookup Tables'!$B$2:$B$7,0),0) + IF(Z11="Yes", IF(IFERROR(_xlfn.XLOOKUP(AJ11,'Lookup Tables'!$A$2:$A$7,'Lookup Tables'!$B$2:$B$7,0),0)<20, 5, 0), 0) + _xlfn.IFS(AB11="Yes", IF(ISNUMBER(AC11)*AND(AC11<=2030),15,10), AB11="Long-term Only", 5, AB11="No", 0, TRUE, 0) + _xlfn.IFS(AF11="Full",10, AF11="Partial",5, AF11="Scope 2 Only",3, TRUE,0) + _xlfn.IFS(AG11="Yes", IF(ISNUMBER(AH11)*AND(AH11>=5),10,6), AG11="Partial",4, TRUE,0) + _xlfn.IFS(AI11="Yes",5, AI11="Partial (material categories only)",3, TRUE,0) + _xlfn.IFS(AL11="Yes — Detailed",10, AL11="Yes — High Level",5, TRUE,0) + _xlfn.IFS(AM11="Yes — Quantified",15, AM11="Yes — Directional Only",7, TRUE,0) + _xlfn.IFS(AP11="Formal",5, AP11="Referenced",2, TRUE,0) + _xlfn.IFS(AQ11="No Issues Found",5, AQ11="Concern Identified",-5, AQ11="Severe Contradiction",-15, TRUE,0) + _xlfn.IFS(BC11="Reasonable Assurance",5, BC11="Limited Assurance",3, TRUE,0) - IF(AND(Z11="Yes", AI11="No"), 10, 0) - IF(AND(Z11="Yes", AM11="No"), 10, 0) ))} | BE11: {=MIN(100, MAX(0, IFERROR(_xlfn.XLOOKUP(AT11,'Lookup Tables'!$D$2:$D$6,'Lookup Tables'!$E$2:$E$6,0),0) + IFERROR(_xlfn.XLOOKUP(AV11,'Lookup Tables'!$G$2:$G$5,'Lookup Tables'!$H$2:$H$5,0),0) + IFERROR(_xlfn.XLOOKUP(AW11,'Lookup Tables'!$J$2:$J$5,'Lookup Tables'!$K$2:$K$5,0),0) + _xlfn.IFS(AX11="No Issues",10, AX11="Complaint Filed",3, AX11="Confirmed Breach",-15, TRUE,0) + IFERROR(_xlfn.XLOOKUP(AY11,'Lookup Tables'!$M$2:$M$6,'Lookup Tables'!$N$2:$N$6,0),0) + IFERROR(_xlfn.XLOOKUP(AZ11,'Lookup Tables'!$P$2:$P$6,'Lookup Tables'!$Q$2:$Q$6,0),0) + _xlfn.IFS(BA11="Formal Board Committee",5, BA11="Board Oversight Mentioned",2, TRUE,0) + _xlfn.IFS(BB11="Yes — Quantified Targets",5, BB11="Yes — Discretionary Only",2, TRUE,0) + _xlfn.IFS(BC11="Reasonable Assurance",5, BC11="Limited Assurance",3, BC11="Management Review Only",1, TRUE,0) ))} | BS11: {=MIN(100, MAX(0, IFERROR(_xlfn.XLOOKUP(BG11,'Lookup Tables'!$A$11:$A$16,'Lookup Tables'!$B$11:$B$16,0),0) + IFERROR(_xlfn.XLOOKUP(BR11,'Lookup Tables'!$M$11:$M$14,'Lookup Tables'!$N$11:$N$14,0),0) + IFERROR(_xlfn.XLOOKUP(BQ11,'Lookup Tables'!$J$11:$J$15,'Lookup Tables'!$K$11:$K$15,0),0) + IFERROR(_xlfn.XLOOKUP(BH11,'Lookup Tables'!$D$11:$D$15,'Lookup Tables'!$E$11:$E$15,0),0) + IFERROR(_xlfn.XLOOKUP(BJ11,'Lookup Tables'!$G$11:$G$16,'Lookup Tables'!$H$11:$H$16,0),0) + IFERROR(_xlfn.XLOOKUP(BN11,'Lookup Tables'!$P$11:$P$15,'Lookup Tables'!$Q$11:$Q$15,0),0) + _xlfn.IFS(BM11="No Evidence",10, BM11="Unknown",3, BM11="Likely",0, BM11="Confirmed",-10, TRUE,3) + IFERROR(_xlfn.XLOOKUP(BP11,'Lookup Tables'!$J$21:$J$24,'Lookup Tables'!$K$21:$K$24,0),0) ))} | CE11: {=MIN(100, MAX(0, IF(ISNUMBER(BV11)*AND(BV11>0), 10, 0) + _xlfn.IFS(BY11="Independently Verified",25, BY11="Yes",15, TRUE,0) + IFERROR(_xlfn.XLOOKUP(BZ11,'Lookup Tables'!$A$21:$A$24,'Lookup Tables'!$B$21:$B$24,0),0) + IFERROR(_xlfn.XLOOKUP(CA11,'Lookup Tables'!$D$21:$D$24,'Lookup Tables'!$E$21:$E$24,0),0) + _xlfn.IFS(ISNUMBER(CB11)*AND(CB11>=11),15, ISNUMBER(CB11)*AND(CB11>=6),10, ISNUMBER(CB11)*AND(CB11>=1),5, TRUE,0) + IFERROR(_xlfn.XLOOKUP(CC11,'Lookup Tables'!$G$21:$G$25,'Lookup Tables'!$H$21:$H$25,0),0) - IF(ISNUMBER(BW11)*AND(ISNUMBER(BV11))*AND(BW11>BV11), 20, 0) - IF(AND(BY11="Yes", ISNUMBER(BW11), BW11>60), 10, 0) ))} | CR11: =COUNTIF(CJ11:CQ11,"FAIL") | CS11: =COUNTIF(CJ11:CQ11,"PARTIAL") | CT11: =COUNTIF(CJ11:CQ11,"MISSING") | CU11: =MIN(100, CR11*15 + CS11*6 + CT11*3 + IFERROR(_xlfn.XLOOKUP(CW11,'Lookup Tables'!$M$21:$M$25,'Lookup Tables'!$N$21:$N$25,0),0) ) | CV11: =IFERROR( CHOOSE( MATCH("FAIL",CJ11:CQ11,0), "1-Specificity","2-Metric","3-Baseline","4-Target", "5-Time Horizon","6-Scope","7-Verification","8-Consistency" ), IFERROR( CHOOSE( MATCH("PARTIAL",CJ11:CQ11,0), "1-Specificity","2-Metric","3-Baseline","4-Target", "5-Time Horizon","6-Scope","7-Verification","8-Consistency" ), "No failures" ) ) | DA11: =IF(OR(CU11>=50,CW11="Material",CW11="Severe",AS11="Material",AS11="Severe",BF11="Material",BF11="Severe — Exclusion Trigger",AND(ISNUMBER(BS11),BS11<30)),"Yes","No") | DB11: =IF(OR(CR11>=6,AW11="Confirmed Violation",AX11="Confirmed Breach"),"Yes — Automatic",IF(CW11="Severe","Yes — Requires Captain Confirmation","No")) | DL11: =IF(OR(IFERROR(VALUE(LEFT(DF11,1)),99)<=2,IFERROR(VALUE(LEFT(DG11,1)),99)<=2),"Flagged","Clear") | DM11: =IF(OR(DA11="Yes",DB11<>"No",DH11="Unverified",DL11="Flagged"),"Yes","No") | DN11: {=MIN(100, IF(ISNUMBER(V11), _xlfn.IFS(V11>=3,25, V11=2,15, V11=1,5, TRUE,0), 0) + IFERROR(_xlfn.IFS(VALUE(LEFT(DF11,1))=5,25, VALUE(LEFT(DF11,1))=4,20, VALUE(LEFT(DF11,1))=3,15, VALUE(LEFT(DF11,1))=2,8, TRUE,0), 15) + IFERROR(_xlfn.IFS(VALUE(LEFT(DG11,1))=5,25, VALUE(LEFT(DG11,1))=4,20, VALUE(LEFT(DG11,1))=3,15, VALUE(LEFT(DG11,1))=2,8, TRUE,0), 15) + _xlfn.IFS(DH11="Fully Verified",25, DH11="Partially Verified",12, TRUE,0) )} | DO11: {=_xlfn.IFS( ISBLANK(AR11), "Insufficient Evidence", AND(AR11>=65, AJ11="Approved"), "Strong", AR11>=65, "Adequate", AR11>=40, "Adequate", AR11>=20, "Weak", TRUE, "Insufficient Evidence" )} | DP11: {=_xlfn.IFS( ISBLANK(BS11), "Insufficient Evidence", BS11>=65, "Strong", BS11>=40, "Adequate", BS11>=20, "Weak", TRUE, "Insufficient Evidence" )} | DQ11: {=_xlfn.IFS( ISBLANK(BE11), "Insufficient Evidence", OR(AW11="Confirmed Violation", AX11="Confirmed Breach"), "Severe — Hard Trigger", BE11>=65, "Strong", BE11>=40, "Adequate", BE11>=20, "Weak", TRUE, "Insufficient Evidence" )} | DR11: {=_xlfn.IFS( ISBLANK(CU11), "Insufficient Evidence", CU11<=20, "Low Risk", CU11<=50, "Moderate Risk", CU11<=75, "High Risk", TRUE, "Very High Risk" )} | DS11: {=_xlfn.IFS( ISBLANK(CE11), "Insufficient Evidence", AND(ISNUMBER(BW11),ISNUMBER(BV11),BW11>BV11), "Overclaiming Risk", CE11>=65, "Strong", CE11>=40, "Adequate", TRUE, "Weak" )} | DT11: =IF(DB11="Yes — Automatic",0,ROUND((IF(ISNUMBER(AR11),AR11,0)*0.3+IF(ISNUMBER(BS11),BS11,0)*0.2+IF(ISNUMBER(BE11),BE11,0)*0.2+IF(ISNUMBER(CE11),CE11,0)*0.15+(100-IF(ISNUMBER(CU11),CU11,50))*0.15)*IF(DN11>=75,1,IF(DN11>=50,0.9,IF(DN11>=25,0.75,0.6))),1)) | DU11: {=_xlfn.IFS( DV11="Upgraded to Clear", "Clear", DV11="Downgraded to Watchlist", "Watchlist", DV11="Downgraded to Exclusion", "Exclusion Risk", DB11="Yes — Automatic", "Exclusion Risk", OR(AW11="Confirmed Violation", AX11="Confirmed Breach"), "Exclusion Risk", OR(V11=0, ISBLANK(V11), DN11<20), "Insufficient Evidence", AND(DT11>=65, DA11="No", DB11="No"), "Clear", OR(DT11>=40, DA11="Yes"), "Watchlist", TRUE, "Exclusion Risk" )} | DW11: {=_xlfn.IFS( DU11="Exclusion Risk", "Exclude — Hard Trigger", DU11="Insufficient Evidence", "Watchlist — Further Evidence Needed", DU11="Watchlist", "Watchlist — Further Evidence Needed", AND(DU11="Clear", DT11>=80), "Include — No Conditions", DU11="Clear", "Include — Monitor", TRUE, "Watchlist — Further Evidence Needed" )} | EB11: =IF(OR(V11=0, ISBLANK(V11)), "MISSING — No sources reviewed", "") | EC11: =IF(AND(NOT(ISBLANK(DC11)), ISBLANK(DE11)), "PAGE REF MISSING", "")
A12: Ackermans & van Haaren NV | B12: B3K | C12: =IF(ISBLANK('Universe Tracker'!D8),"",'Universe Tracker'!D8) | F12: =IF(ISBLANK('Universe Tracker'!F8),"",'Universe Tracker'!F8) | G12: =IF(ISBLANK('Universe Tracker'!G8),"",'Universe Tracker'!G8) | J12: =IF(ISBLANK(B12),"",B12&"_"&C12) | Y12: =IF(AND(V12>=2,K12="Yes",L12="Yes"),"Sufficient",IF(AND(V12>=1,OR(K12="Yes",L12="Yes")),"Thin","Insufficient")) | AR12: {=MIN(100, MAX(0, IFERROR(_xlfn.XLOOKUP(AJ12,'Lookup Tables'!$A$2:$A$7,'Lookup Tables'!$B$2:$B$7,0),0) + IF(Z12="Yes", IF(IFERROR(_xlfn.XLOOKUP(AJ12,'Lookup Tables'!$A$2:$A$7,'Lookup Tables'!$B$2:$B$7,0),0)<20, 5, 0), 0) + _xlfn.IFS(AB12="Yes", IF(ISNUMBER(AC12)*AND(AC12<=2030),15,10), AB12="Long-term Only", 5, AB12="No", 0, TRUE, 0) + _xlfn.IFS(AF12="Full",10, AF12="Partial",5, AF12="Scope 2 Only",3, TRUE,0) + _xlfn.IFS(AG12="Yes", IF(ISNUMBER(AH12)*AND(AH12>=5),10,6), AG12="Partial",4, TRUE,0) + _xlfn.IFS(AI12="Yes",5, AI12="Partial (material categories only)",3, TRUE,0) + _xlfn.IFS(AL12="Yes — Detailed",10, AL12="Yes — High Level",5, TRUE,0) + _xlfn.IFS(AM12="Yes — Quantified",15, AM12="Yes — Directional Only",7, TRUE,0) + _xlfn.IFS(AP12="Formal",5, AP12="Referenced",2, TRUE,0) + _xlfn.IFS(AQ12="No Issues Found",5, AQ12="Concern Identified",-5, AQ12="Severe Contradiction",-15, TRUE,0) + _xlfn.IFS(BC12="Reasonable Assurance",5, BC12="Limited Assurance",3, TRUE,0) - IF(AND(Z12="Yes", AI12="No"), 10, 0) - IF(AND(Z12="Yes", AM12="No"), 10, 0) ))} | BE12: {=MIN(100, MAX(0, IFERROR(_xlfn.XLOOKUP(AT12,'Lookup Tables'!$D$2:$D$6,'Lookup Tables'!$E$2:$E$6,0),0) + IFERROR(_xlfn.XLOOKUP(AV12,'Lookup Tables'!$G$2:$G$5,'Lookup Tables'!$H$2:$H$5,0),0) + IFERROR(_xlfn.XLOOKUP(AW12,'Lookup Tables'!$J$2:$J$5,'Lookup Tables'!$K$2:$K$5,0),0) + _xlfn.IFS(AX12="No Issues",10, AX12="Complaint Filed",3, AX12="Confirmed Breach",-15, TRUE,0) + IFERROR(_xlfn.XLOOKUP(AY12,'Lookup Tables'!$M$2:$M$6,'Lookup Tables'!$N$2:$N$6,0),0) + IFERROR(_xlfn.XLOOKUP(AZ12,'Lookup Tables'!$P$2:$P$6,'Lookup Tables'!$Q$2:$Q$6,0),0) + _xlfn.IFS(BA12="Formal Board Committee",5, BA12="Board Oversight Mentioned",2, TRUE,0) + _xlfn.IFS(BB12="Yes — Quantified Targets",5, BB12="Yes — Discretionary Only",2, TRUE,0) + _xlfn.IFS(BC12="Reasonable Assurance",5, BC12="Limited Assurance",3, BC12="Management Review Only",1, TRUE,0) ))} | BS12: {=MIN(100, MAX(0, IFERROR(_xlfn.XLOOKUP(BG12,'Lookup Tables'!$A$11:$A$16,'Lookup Tables'!$B$11:$B$16,0),0) + IFERROR(_xlfn.XLOOKUP(BR12,'Lookup Tables'!$M$11:$M$14,'Lookup Tables'!$N$11:$N$14,0),0) + IFERROR(_xlfn.XLOOKUP(BQ12,'Lookup Tables'!$J$11:$J$15,'Lookup Tables'!$K$11:$K$15,0),0) + IFERROR(_xlfn.XLOOKUP(BH12,'Lookup Tables'!$D$11:$D$15,'Lookup Tables'!$E$11:$E$15,0),0) + IFERROR(_xlfn.XLOOKUP(BJ12,'Lookup Tables'!$G$11:$G$16,'Lookup Tables'!$H$11:$H$16,0),0) + IFERROR(_xlfn.XLOOKUP(BN12,'Lookup Tables'!$P$11:$P$15,'Lookup Tables'!$Q$11:$Q$15,0),0) + _xlfn.IFS(BM12="No Evidence",10, BM12="Unknown",3, BM12="Likely",0, BM12="Confirmed",-10, TRUE,3) + IFERROR(_xlfn.XLOOKUP(BP12,'Lookup Tables'!$J$21:$J$24,'Lookup Tables'!$K$21:$K$24,0),0) ))} | CE12: {=MIN(100, MAX(0, IF(ISNUMBER(BV12)*AND(BV12>0), 10, 0) + _xlfn.IFS(BY12="Independently Verified",25, BY12="Yes",15, TRUE,0) + IFERROR(_xlfn.XLOOKUP(BZ12,'Lookup Tables'!$A$21:$A$24,'Lookup Tables'!$B$21:$B$24,0),0) + IFERROR(_xlfn.XLOOKUP(CA12,'Lookup Tables'!$D$21:$D$24,'Lookup Tables'!$E$21:$E$24,0),0) + _xlfn.IFS(ISNUMBER(CB12)*AND(CB12>=11),15, ISNUMBER(CB12)*AND(CB12>=6),10, ISNUMBER(CB12)*AND(CB12>=1),5, TRUE,0) + IFERROR(_xlfn.XLOOKUP(CC12,'Lookup Tables'!$G$21:$G$25,'Lookup Tables'!$H$21:$H$25,0),0) - IF(ISNUMBER(BW12)*AND(ISNUMBER(BV12))*AND(BW12>BV12), 20, 0) - IF(AND(BY12="Yes", ISNUMBER(BW12), BW12>60), 10, 0) ))} | CR12: =COUNTIF(CJ12:CQ12,"FAIL") | CS12: =COUNTIF(CJ12:CQ12,"PARTIAL") | CT12: =COUNTIF(CJ12:CQ12,"MISSING") | CU12: =MIN(100, CR12*15 + CS12*6 + CT12*3 + IFERROR(_xlfn.XLOOKUP(CW12,'Lookup Tables'!$M$21:$M$25,'Lookup Tables'!$N$21:$N$25,0),0) ) | CV12: =IFERROR( CHOOSE( MATCH("FAIL",CJ12:CQ12,0), "1-Specificity","2-Metric","3-Baseline","4-Target", "5-Time Horizon","6-Scope","7-Verification","8-Consistency" ), IFERROR( CHOOSE( MATCH("PARTIAL",CJ12:CQ12,0), "1-Specificity","2-Metric","3-Baseline","4-Target", "5-Time Horizon","6-Scope","7-Verification","8-Consistency" ), "No failures" ) ) | DA12: =IF(OR(CU12>=50,CW12="Material",CW12="Severe",AS12="Material",AS12="Severe",BF12="Material",BF12="Severe — Exclusion Trigger",AND(ISNUMBER(BS12),BS12<30)),"Yes","No") | DB12: =IF(OR(CR12>=6,AW12="Confirmed Violation",AX12="Confirmed Breach"),"Yes — Automatic",IF(CW12="Severe","Yes — Requires Captain Confirmation","No")) | DL12: =IF(OR(IFERROR(VALUE(LEFT(DF12,1)),99)<=2,IFERROR(VALUE(LEFT(DG12,1)),99)<=2),"Flagged","Clear") | DM12: =IF(OR(DA12="Yes",DB12<>"No",DH12="Unverified",DL12="Flagged"),"Yes","No") | DN12: {=MIN(100, IF(ISNUMBER(V12), _xlfn.IFS(V12>=3,25, V12=2,15, V12=1,5, TRUE,0), 0) + IFERROR(_xlfn.IFS(VALUE(LEFT(DF12,1))=5,25, VALUE(LEFT(DF12,1))=4,20, VALUE(LEFT(DF12,1))=3,15, VALUE(LEFT(DF12,1))=2,8, TRUE,0), 15) + IFERROR(_xlfn.IFS(VALUE(LEFT(DG12,1))=5,25, VALUE(LEFT(DG12,1))=4,20, VALUE(LEFT(DG12,1))=3,15, VALUE(LEFT(DG12,1))=2,8, TRUE,0), 15) + _xlfn.IFS(DH12="Fully Verified",25, DH12="Partially Verified",12, TRUE,0) )} | DO12: {=_xlfn.IFS( ISBLANK(AR12), "Insufficient Evidence", AND(AR12>=65, AJ12="Approved"), "Strong", AR12>=65, "Adequate", AR12>=40, "Adequate", AR12>=20, "Weak", TRUE, "Insufficient Evidence" )} | DP12: {=_xlfn.IFS( ISBLANK(BS12), "Insufficient Evidence", BS12>=65, "Strong", BS12>=40, "Adequate", BS12>=20, "Weak", TRUE, "Insufficient Evidence" )} | DQ12: {=_xlfn.IFS( ISBLANK(BE12), "Insufficient Evidence", OR(AW12="Confirmed Violation", AX12="Confirmed Breach"), "Severe — Hard Trigger", BE12>=65, "Strong", BE12>=40, "Adequate", BE12>=20, "Weak", TRUE, "Insufficient Evidence" )} | DR12: {=_xlfn.IFS( ISBLANK(CU12), "Insufficient Evidence", CU12<=20, "Low Risk", CU12<=50, "Moderate Risk", CU12<=75, "High Risk", TRUE, "Very High Risk" )} | DS12: {=_xlfn.IFS( ISBLANK(CE12), "Insufficient Evidence", AND(ISNUMBER(BW12),ISNUMBER(BV12),BW12>BV12), "Overclaiming Risk", CE12>=65, "Strong", CE12>=40, "Adequate", TRUE, "Weak" )} | DT12: =IF(DB12="Yes — Automatic",0,ROUND((IF(ISNUMBER(AR12),AR12,0)*0.3+IF(ISNUMBER(BS12),BS12,0)*0.2+IF(ISNUMBER(BE12),BE12,0)*0.2+IF(ISNUMBER(CE12),CE12,0)*0.15+(100-IF(ISNUMBER(CU12),CU12,50))*0.15)*IF(DN12>=75,1,IF(DN12>=50,0.9,IF(DN12>=25,0.75,0.6))),1)) | DU12: {=_xlfn.IFS( DV12="Upgraded to Clear", "Clear", DV12="Downgraded to Watchlist", "Watchlist", DV12="Downgraded to Exclusion", "Exclusion Risk", DB12="Yes — Automatic", "Exclusion Risk", OR(AW12="Confirmed Violation", AX12="Confirmed Breach"), "Exclusion Risk", OR(V12=0, ISBLANK(V12), DN12<20), "Insufficient Evidence", AND(DT12>=65, DA12="No", DB12="No"), "Clear", OR(DT12>=40, DA12="Yes"), "Watchlist", TRUE, "Exclusion Risk" )} | DW12: {=_xlfn.IFS( DU12="Exclusion Risk", "Exclude — Hard Trigger", DU12="Insufficient Evidence", "Watchlist — Further Evidence Needed", DU12="Watchlist", "Watchlist — Further Evidence Needed", AND(DU12="Clear", DT12>=80), "Include — No Conditions", DU12="Clear", "Include — Monitor", TRUE, "Watchlist — Further Evidence Needed" )} | EB12: =IF(OR(V12=0, ISBLANK(V12)), "MISSING — No sources reviewed", "") | EC12: =IF(AND(NOT(ISBLANK(DC12)), ISBLANK(DE12)), "PAGE REF MISSING", "")
